Workbook

Sheet 시트1
A1: NAME_KR | B1: NAME_EN | C1: COUNTRY | D1: INTRO_KR | E1: INTRO_EN | F1: WEBSITE | G1: PARTICIPATION_TYPE | H1: EXHIBITION_NAME_EN | I1: BOOTH_NAME | J1: FLOOR | K1: X_COORD | L1: Y_COORD | M1: INDUSTRY_NAME_KR | N1: INDUSTRY_NAME_EN
A2: LG에너지솔루션 | B2: LG Energy Solution | C2: South Korea | D2: LG에너지솔루션 주식회사는 2020년 12월 LG화학의 전지사업부가 분할되어 설립된 글로벌 리튬이온 배터리 제조 기업이다. 본사는 대한민국 서울에 위치하며, 전기자동차용 배터리, IT기기 및 소형 모빌리티용 배터리, 에너지저장장치(ESS)용 배터리를 생산한다. 주요 사업은 셀(Cell), 모듈(Module), 팩(Pack), 배터리관리시스템(BMS) 제조 및 ESS 시스템 통합이다. | E2: LG Energy Solution, Ltd. is a global lithium-ion battery manufacturer established in December 2020 through the spin-off of LG Chem’s battery division. Headquartered in Seoul, South Korea, the company produces batteries for electric vehicles, IT devices, small mobility applications, and energy storage systems (ESS). Its main businesses include the production of cells, modules, packs, battery management systems (BMS), and ESS system integration. | F2: http://www.lgensol.com/ | G2: Exhibitor | H2: InterBattery Europe 2025 | I2: C3.410 | J2: 1F | K2: {=XLOOKUP(I2, Sheet1!$A:$A, Sheet1!$B:$B, "")} -> 3951 | L2: {=XLOOKUP(I2, Sheet1!$A:$A, Sheet1!$C:$C, "")} -> 151 | M2: 리튬이온 배터리; 전기자동차 배터리; 소형 IT·모빌리티 배터리; 에너지저장장치(ESS) | N2: Lithium-ion Batteries; Electric Vehicle Batteries; IT & Mobility Batteries; Energy Storage Systems (ESS)
A3: 삼성SDI | B3: Samsung SDI | C3: South Korea | D3: 삼성SDI 주식회사는 1970년에 설립된 한국의 배터리 및 전자 소재 전문 기업이다. 본사는 경기도 용인에 있으며, IT기기, 전기차(EV), 에너지저장장치(ESS)용 리튬이온 배터리를 제조한다. 또한 반도체 및 디스플레이용 전자 소재 사업도 운영하며, 차세대 배터리 기술 및 고성능 소재 개발을 위해 지속적으로 연구개발(R&D)에 투자하고 있다. | E3: Samsung SDI, headquartered in the Republic of Korea, is a world-leading battery and electronic material manufacturer redefining the worlds of electric vehicles, energy storage systems and IT devices. The company drives transformation and innovation to emerge as a ‘Creative Energy and Materials Solution Leader’ across the fields of e-mobility, energy solutions, as well as semiconductors and displays. The company commits to sourcing 100% renewable electricity across its entire global operations by 2050. For the latest news, please visit the Samsung SDI News at https://www.samsungsdi.com | F3: http://www.samsungsdi.co.kr/ | G3: Exhibitor | H3: InterBattery Europe 2025 | I3: C3.310 | J3: 1F | K3: {=XLOOKUP(I3, Sheet1!$A:$A, Sheet1!$B:$B, "")} -> 3990 | L3: {=XLOOKUP(I3, Sheet1!$A:$A, Sheet1!$C:$C, "")} -> 253 | M3: 리튬이온 배터리; 전기차 배터리; IT기기용 배터리; 에너지저장장치(ESS); 전자 소재(반도체·디스플레이) | N3: Lithium-ion Batteries; Electric Vehicle (EV) Batteries; IT & Mobility Device Batteries; Energy Storage Systems (ESS); Electronic Materials (Semiconductors & Displays)
A4: 제이스텍 | B4: JASTECH,Ltd. | C4: South Korea | D4: 제이스텍(주식회사 제이스텍)은 1995년 3월 설립된 한국의 제조업체로, 충청남도 아산시에 본사를 두고 있다. 주 사업 영역은 디스플레이 본딩장비, 반도체 세척·도금 장비, 레이저 가공장비, 2차전지 장비, 바이오진단 키트 자동화 장비, 물류 로봇 등이 있다. 코스닥 상장 기업이며, 연구개발 및 설비 사업의 다각화를 통해 신성장 분야로의 확장을 추진 중이다 | E4: JASTECH provides advanced manufacturing solutions for prismatic CAN-type battery cells. Our portfolio includes high-precision cell assembly and cap assembly equipment, along with prismatic cell housings using deep drawing and extruded CAN technologies. We also produce essential components such as cap plates, vents, etc. With integrated capabilities in cell design, manufacturing, component production, and equipment engineering, JASTECH delivers a full turnkey solution for prismatic cell production. We are currently building a state-of-the-art gigafactory in India. | F4: http://jastech.co.kr/index.html | G4: Exhibitor | H4: InterBattery Europe 2025 | I4: C3.460 | J4: 1F | K4: {=XLOOKUP(I4, Sheet1!$A:$A, Sheet1!$B:$B, "")} -> 3433 | L4: {=XLOOKUP(I4, Sheet1!$A:$A, Sheet1!$C:$C, "")} -> 269 | M4: 디스플레이 장비; 반도체 장비; 레이저 가공 장비; 세척·도금 장비; 이차전지 장비; 바이오진단 자동화 장비; 물류 로봇 | N4: Display Equipment; Semiconductor Equipment; Laser Processing Equipment; Cleaning & Plating Equipment; Secondary Battery Equipment; Bio-diagnostic Automation Equipment; Logistics Robots
A5: 에너테크 인터내셔널 | B5: EnerTech International | C5: South Korea | D5: 에너테크인터내셔널 주식회사는 2001년 설립된 대한민국 충청북도 충주 소재의 리튬이온 배터리 전문 기업이다. 회사는 새한미디어 등에서 개발한 비디오테이프 코팅 기술을 기반으로 전극(극판) 코팅 기술을 확보하였으며, 이후 EV(전기자동차), ESS(에너지저장장치), UPS, 의료기기 등 고출력 배터리 시스템을 설계·제작한다. 주요 제품은 전극, 셀(Cell), 모듈(Module), 팩(Pack), 배터리 시스템 및 대면적(Large-format) 배터리이고, 일부 제품을 미국, 유럽, 캐나다, 러시아 등 여러 국가로 수출하고 있다. 또한 소듐이온(Na-ion) 배터리 개발 중이며, 2027년 양산 시작을 목표로 하고 있다. | E5: ENERTECH International Inc. has leveraged its early expertise in producing magnetic videotape and re-writable compact disks into a successful business coating electrodes for lithium-ion batteries. Our experience coating Electrodes with Nano-Materials, EnerTech International allows us to improve the performance and quality of Large format batteries that are in demand with emerging market applications such as Electric Vehicle, HEV and UPS Telecommunication. | F5: http://www.enertechint.com/ | G5: Exhibitor | H5: InterBattery Europe 2025 | I5: C3.530 | J5: 1F | K5: {=XLOOKUP(I5, Sheet1!$A:$A, Sheet1!$B:$B, "")} -> 3789 | L5: {=XLOOKUP(I5, Sheet1!$A:$A, Sheet1!$C:$C, "")} -> 205 | M5: 리튬이온 배터리; 전극 코팅 기술; 전기차 배터리 시스템; 에너지저장장치(ESS) 배터리; UPS 배터리 시스템; 대면적 배터리; 소듐이온 배터리 개발 | N5: Lithium-ion Battery Manufacturing; Electrode Coating Technology; EV Battery Systems; ESS Battery Systems; UPS Battery Systems; Large-format Batteries; Sodium-ion Battery Development
A6: 재단법인충북테크노파크 | B6: CHUNGBUK TECHNOPARK | C6: South Korea | D6: 재단법인 충북테크노파크는 2003년 12월 설립된 비영리 공공 기술혁신 기관으로, 충청북도 청주시 오창 소재이다. 지역 산업 기술 기반 조성, 중소·벤처기업 지원, 기술 사업화 및 창업 인큐베이션, 전략 산업 육성, 연구장비 제공 및 기술실증 등 다양한 기술지원 서비스를 수행한다. 또한 반도체 및 전자정보부품, 바이오헬스, 에너지 신산업, 스마트IT부품, 소비재 산업 등 지역 전략 산업의 경쟁력 강화를 위한 사업을 운영한다. | E6: Chungbuk Technopark is a non-profit public innovation organization established in December 2003, located in Ochang, Cheongju, North Chungcheong Province, South Korea. It serves as a regional technology hub providing support for SME & venture companies through business incubation, technology commercialization, R&D infrastructure, and equipment provision. The organization fosters strategic industries such as semiconductor and electronic parts, bio-health, energy new industry, smart IT components, and premium consumer goods, and implements programs for regional industrial development, workforce training, and innovation ecosystem building. | F6: http://www.cbtp.or.kr/ | G6: Exhibitor | H6: InterBattery Europe 2025 | I6: C3.640 | J6: 1F | K6: {=XLOOKUP(I6, Sheet1!$A:$A, Sheet1!$B:$B, "")} -> 3671 | L6: {=XLOOKUP(I6, Sheet1!$A:$A, Sheet1!$C:$C, "")} -> 152 | M6: 기술혁신 및 사업화 지원; 창업 인큐베이션; 반도체 및 전자부품; 바이오헬스; 에너지 신산업; 스마트 IT 부품; 소비재 산업; 연구장비 및 기술실증; 중소·벤처기업 지원 | N6: Technology Innovation & Commercialization Support; Startup Incubation; Semiconductor & Electronic Components; Bio-Health Industry; New Energy Industries; Smart IT Components; Consumer Goods; Research Equipment & Demonstration; SME & Venture Support
A7: 에버모어테크놀러지스 | B7: EVERMORE TECHNOLOGIES | C7: South Korea | D7: 에버모어테크놀러지스(Evermore Technologies Inc.)는 2024년 1월 설립된 대한민국 전라남도 나주 소재의 이차전지용 부품·소재 전문기업이다. 실리콘 음극재, 바이오 기반 탄소소재, 반고체 전해질 등 차세대 배터리 소재를 개발하며, ‘ARC 센터(Advanced Research Center)’를 나주에 구축하여 소재 합성부터 셀 조립 및 성능 시험까지 파일럿 라인을 갖춘 연구개발 허브로 운영 중이다. 대표는 박진수이며, 기타 이차전지 제조업 표준산업분류에 속해 있다. | E7: Evermore Technologies is a leading innovator in next-generation battery materials, providing high-efficiency battery solutions that overcome the limitations of silicon anode materials. Through proprietary formulation technology, we have maintained silicon’s high-capacity characteristics while solving its expansion issues, thereby maximizing battery performance and lifespan. Additionally, we have adopted eco-friendly production processes, developing sustainable battery materials by utilizing recycled silicon wafers and RCBW(Recycled Cattle Bio Waste) Material. Our cutting-edge technology is designed for the electric vehicle, E-Mobility, and energy storage system (ESS) markets. | F7: http://www.goevermore.com/ | G7: Exhibitor | H7: InterBattery Europe 2025 | I7: C3.430 | J7: 1F | K7: {=XLOOKUP(I7, Sheet1!$A:$A, Sheet1!$B:$B, "")} -> 3802 | L7: {=XLOOKUP(I7, Sheet1!$A:$A, Sheet1!$C:$C, "")} -> 268 | M7: 이차전지 소재; 이차전지 부품; 실리콘 음극재; 바이오 기반 탄소소재; 반고체 전해질; 배터리 셀 조립; 배터리 성능 시험; 연구개발(R&D) 허브 | N7: Secondary Battery Materials; Secondary Battery Components; Silicon Anode Materials; Bio-based Carbon Materials; Semi-solid Electrolytes; Battery Cell Assembly; Battery Performance Testing; R&D Hub
A8: 비나텍 | B8: VINATech Co.,Ltd. | C8: South Korea | D8: 비나텍 주식회사는 1999년 7월 설립된 대한민국 전라북도 전주시 덕진구 소재의 친환경 에너지 소재·부품 전문기업이다. 슈퍼커패시터 및 연료전지 부품 (지지체, 촉매, MEA, 분리판, 탈취필터 등) 기술을 연구·개발하고 제조하며, 코스닥 상장 기업이다 (상장일: 2020년 9월 23일). 글로벌 네트워크를 통해 맞춤형 슈퍼커패시터 모듈과 연료전지 핵심소재를 공급하며, 국내외 수요처에 제품을 수출하고 있다 | E8: VINATech Co., Ltd., founded on July 26, 1999, is a South Korean clean energy materials & components company headquartered in Jeonju, North Jeolla Province. It develops, manufactures, and supplies supercapacitors and fuel cell components including supports, catalysts, MEA (Membrane Electrode Assembly), bipolar plates, and odor removal filters. VINATech is listed on KOSDAQ since September 23, 2020, and provides customized supercapacitor modules and fuel cell key materials, exporting to markets globally | F8: https://www.vinatech.com/ | G8: Exhibitor | H8: InterBattery Europe 2025 | I8: C3.630 | J8: 1F | K8: {=XLOOKUP(I8, Sheet1!$A:$A, Sheet1!$B:$B, "")} -> 3799 | L8: {=XLOOKUP(I8, Sheet1!$A:$A, Sheet1!$C:$C, "")} -> 142 | M8: 슈퍼커패시터 제조; 슈퍼커패시터 모듈; 연료전지 소재; 연료전지 부품; 지지체; 촉매; MEA; 분리판; 탈취필터; 에너지 저장 솔루션 | N8: Supercapacitor Manufacturing; Supercapacitor Modules; Fuel Cell Materials; Fuel Cell Components; Supports; Catalysts; MEA (Membrane Electrode Assembly); Bipolar Plates; Filters; Energy Storage Solutions
A9: 에이치투 | B9: H2, Inc. | C9: South Korea | D9: ㈜에이치투(H2, Inc.)는 2010년 8월 설립된 대한민국 대전 소재 기업으로, 바나듐 레독스 흐름전지 (Vanadium Redox Flow Battery, VRFB) 분야의 ESS(에너지 저장 시스템) 전문업체이다. VFB ESS의 연구개발, 설계 및 제조를 수행하며, 국내 최초 상용 VFB ESS 출시 및 MW급 설치 실적을 보유하고 있다. 대표 제품군으로는 EnerFLOW 시리즈가 있으며, 중장기 에너지저장시장 및 그리드 연계형 ESS 사업을 확대 중이다. | E9: H2, Inc. is a South Korean company founded in August 2010, based in Daejeon, specializing in Vanadium Redox Flow Batteries (VRFB) for Energy Storage Systems (ESS). The company engages in R&D, design, and manufacture of VFB ESS, and holds commercial experience including the first domestic offering of VFB ESS and MW-scale installations. Its core product line is the EnerFLOW series, and it is expanding into large-scale, grid-connected ESS projects | F9: http://www.h2aec.com/ | G9: Exhibitor | H9: InterBattery Europe 2025 | I9: C3.450 | J9: 1F | K9: {=XLOOKUP(I9, Sheet1!$A:$A, Sheet1!$B:$B, "")} -> 3571 | L9: {=XLOOKUP(I9, Sheet1!$A:$A, Sheet1!$C:$C, "")} -> 268 | M9: 바나듐 레독스 흐름전지; 에너지저장시스템(ESS); 대용량 배터리; 시스템 설계 및 제조 | N9: Vanadium Redox Flow Battery; Energy Storage Systems (ESS); Large-scale Battery Systems; System Design & Manufacturing
A10: 씨엔피솔루션즈 | B10: CNP Solutions Co., LTD. | C10: South Korea | D10: 씨엔피솔루션즈 주식회사는 한국 서울 성북구에 본사를 둔 소재 전문 기업으로, 2017년에 설립되었다. 회사는 이차전지용 바인더(Binder), 전도성 부가제(conductive additive) 등을 포함한 전극 재료를 개발 및 상업화하고 있으며, 특히 리튬-이온 배터리의 드라이 프로세스(dry process)용 바인더 기술 개발에 주력한다. 또한 기능성 신소재 및 SEM 분석 기술도 보유하고 있으며, 산업 파트너 맞춤형 소재 솔루션을 제공한다. | E10: CNP Solutions Co., Ltd., established in 2017 and headquartered in Seongbuk-gu, Seoul, South Korea, is a materials company specializing in electrode materials for secondary batteries. The company develops and commercializes binders (both wet and dry process), conductive additives, and functional new materials, with particular expertise in dry-process binder technology for lithium-ion and solid-state batteries. It also provides SEM services and customized material solutions for its industrial partners. | F10: https://cnp-sol.com/ | G10: Exhibitor | H10: InterBattery Europe 2025 | I10: C3.534 | J10: 1F | K10: {=XLOOKUP(I10, Sheet1!$A:$A, Sheet1!$B:$B, "")} -> 3752 | L10: {=XLOOKUP(I10, Sheet1!$A:$A, Sheet1!$C:$C, "")} -> 205 | M10: 이차전지 재료; 바인더; 전도성 부가제; 기능성 신소재; 드라이 프로세스 바인더; SEM 분석 | N10: Secondary Battery Materials; Binders; Conductive Additives; Functional New Materials; Dry-Process Binders; SEM Analysis
A11: 비츠로셀 | B11: Vitzrocell | C11: South Korea | D11: 비츠로셀 주식회사는 1987년 10월 설립된 대한민국 충청남도 당진시에 본사를 둔 축전지 전문기업이다. 주로 리튬 1차 전지(Li-SOCl₂, Li-MnO₂, Bobbin/Spiral 타입), 초고온 전지, EDLC(전기 이중층 커패시터), Thin Film 배터리, 특수 리튬 이온 배터리 제품을 개발 및 제조한다. 또한 메모리 백업, 디지털 미터, 통신 장비 등 다양한 응용 기기에 제품을 공급하고 있으며 코스닥 상장 회사이다 | E11: Vitzrocell Co., Ltd., founded in October 1987, is a battery manufacturer based in Dangjin-si, Chungcheongnam-do, South Korea. The company produces primary lithium batteries (e.g. Li-SOCl₂, Li-MnO₂) in bobbin and spiral formats, high-temperature batteries, EDLC (Electric Double Layer Capacitors), thin-film batteries, and specialized lithium‐ion batteries. It supplies its products to applications such as memory backup, digital meters, communication devices, and other portable power needs. Vitzrocell is listed on the KOSDAQ | F11: http://www.vitzrocell.co.kr/ | G11: Exhibitor | H11: InterBattery Europe 2025 | I11: C3.538 | J11: 1F | K11: {=XLOOKUP(I11, Sheet1!$A:$A, Sheet1!$B:$B, "")} -> 3676 | L11: {=XLOOKUP(I11, Sheet1!$A:$A, Sheet1!$C:$C, "")} -> 215 | M11: 리튬 1차 전지; 초고온 전지; 전기 이중층 커패시터 (EDLC); Thin Film 배터리; 특수 리튬이온 배터리; 휴대용 전원 솔루션; 메모리 백업·디지털 미터 응용 | N11: Primary Lithium Batteries; High-Temperature Batteries; Electric Double Layer Capacitors (EDLC); Thin Film Batteries; Specialty Lithium-Ion Batteries; Portable Power Solutions; Memory Backup & Digital Meter Applications
A12: 대전테크노파크 | B12: DAEJEON TECHNOPARK | C12: South Korea | D12: 재단법인 대전테크노파크는 2008년 3월 설립된 지역 기술혁신 거점 기관으로, 대전광역시를 중심으로 첨단 융복합 산업 및 강소기업 육성을 통해 지역경제 활성화를 도모한다. 산·학·연·관 간 협력체제를 구축하고, 창업보육, 기술사업화, 연구개발 인프라 제공, 기업 경쟁력 제고를 위한 시장·경쟁력 지원사업을 수행한다. | E12: Daejeon Technopark (DJTP) is a public innovation hub established in March 2008, based in Daejeon, South Korea. It acts as a regional technology & industrial catalyst that cultivates small and medium enterprises (SMEs), supports advanced convergence industries, and promotes economic revitalization in the region. DJTP facilitates collaboration among academia, research institutes, government, and industry; provides incubation for startups; offers R&D infrastructure; and runs programs for technology commercialization and market competitiveness enhancement. | F12: https://www.djtp.or.kr/ | G12: Exhibitor | H12: InterBattery Europe 2025 | I12: C3.639 | J12: 1F | K12: {=XLOOKUP(I12, Sheet1!$A:$A, Sheet1!$B:$B, "")} -> 3673 | L12: {=XLOOKUP(I12, Sheet1!$A:$A, Sheet1!$C:$C, "")} -> 193 | M12: 기술혁신 거점 지원; 창업보육; 연구개발 인프라 제공; 기술사업화; 기업 경쟁력 강화; 첨단 융복합 산업 육성; 지역 산업 활성화 | N12: Innovation Hub Support; Startup Incubation; R&D Infrastructure Provision; Technology Commercialization; Enterprise Competitiveness Enhancement; Advanced Convergence Industry Development; Regional Industrial Revitalization
A13: 투에스티 | B13: SST Co., Ltd. | C13: South Korea | D13: 주식회사 투에스티(SST Co., Ltd.)는 대한민국 인천 남동구에 본사를 둔 기업으로, “안전과 에너지 절감”을 기업 미션으로 한다. 전기 및 배터리 화재의 예방과 피해 최소화를 위해, 화재 초기 대응용 소화용구, 확산방지 시스템, 분전반 및 케이블용 화재 차단 장치, 무전원 무선센서 및 IoT 기반 화재 감지/알림 제품 등을 개발·공급한다 | E13: SST Co., Ltd. is a South Korean company based in Namdong-gu, Incheon. Operating under the motto of safety and energy saving, the company designs and supplies fire prevention and suppression solutions for electric and battery-related fire risks. Its product portfolio includes fire extinguishing tools, fire spread prevention systems, panels and cable fire barrier devices, passive or non-power wireless sensors, and IoT-based fire detection and alerting systems | F13: http://www.two-st.com/ | G13: Exhibitor | H13: InterBattery Europe 2025 | I13: C3.650 | J13: 1F | K13: {=XLOOKUP(I13, Sheet1!$A:$A, Sheet1!$B:$B, "")} -> 3577 | L13: {=XLOOKUP(I13, Sheet1!$A:$A, Sheet1!$C:$C, "")} -> 155 | M13: 전기화재 예방; 배터리 화재 소화용구; 화재 확산 방지 시스템; 무전원 무선센서; IoT 화재 감지 & 알림; 화재 안전장치 | N13: Electrical Fire Prevention; Battery Fire Suppression Tools; Fire Spread Prevention Systems; Passive Wireless Sensors; IoT Fire Detection & Alerting; Fire Safety Devices
... A58: Shenzhen Minglida Precision Technology Co., Ltd. | B58: Shenzhen Minglida Precision Technology Co., Ltd. | C58: China | D58: Shenzhen Minglida Precision Technology Co., Ltd.(약칭 MLD, 주식코드: 301268)는 2004년 설립되어 중국 선전 난산구에 본사를 두고 있으며, 현재 9개의 자회사와 중국 내외 6개의 생산기지를 운영하고 5,000명 이상의 직원을 보유한 글로벌 정밀 구조 부품 종합 제조 기업이다. 주요 사업은 태양광, 에너지 저장, 신에너지 차량 등 분야를 포괄하며, 정밀 다이캐스팅, 정밀 사출 성형, 정밀 압출, 정밀 스탬핑, 연결 부품 등 전 산업 체인을 아우르는 서비스를 제공할 수 있는 역량을 갖추고 있다. MLD는 “고객 중심”을 핵심 가치로 삼고 있으며, 화남, 화동, 화중, 서남 지역 등 중국 전역과 해외 시장에서 산업단지, 글로벌 제품 개발, 다국적 공급망 운영, 지역 산업 기반을 통해 사업을 확장하고 있다. | E58: Shenzhen Minglida Precision Technology Co., Ltd. (Abbreviation: MLD; Stock code: 301268), founded in 2004 and headquartered in Nanshan, Shenzhen, operates 9 subsidiaries and 6 production bases both domestically and overseas, with more than 5,000 employees worldwide. MLD is committed to becoming the world’s leading one-stop precision structural parts manufacturer. Its main business covers photovoltaic, energy storage, new energy vehicles, and related fields, with full industry-chain capabilities in precision structural parts, including precision die casting, injection molding, extrusion profiles, stamping, and connecting components. Guided by a customer-centric philosophy, MLD allocates resources globally, with business layouts across South China, East China, Central China, Southwest China, and continuously expands into overseas markets through industrial parks, global product development, multinational supply chain operations, and regional industry clusters. | F58: https://www.minglidagroup.com/ | G58: Exhibitor | H58: InterBattery Europe 2025 | I58: C3.770 | J58: 1F | K58: {=XLOOKUP(I58, Sheet1!$A:$A, Sheet1!$B:$B, "")} -> 3333 | L58: {=XLOOKUP(I58, Sheet1!$A:$A, Sheet1!$C:$C, "")} -> 90 | M58: 정밀 구조 부품; 정밀 다이캐스팅; 정밀 사출 성형; 정밀 압출 프로파일; 정밀 스탬핑; 연결 부품; 태양광(PV); 에너지 저장(ESS); 신에너지 차량(NEV); 글로벌 공급망 운영 | N58: Precision Structural Parts; Precision Die Casting; Precision Injection Molding; Precision Extrusion Profiles; Precision Stamping; Connecting Components; Photovoltaic (PV); Energy Storage Systems (ESS); New Energy Vehicles (NEV); Global Supply Chain Operations
A59: Jiangxi SinNET Electronics Technologies Co.,Ltd | B59: Jiangxi SinNET Electronics Technologies Co.,Ltd | C59: China | D59: SinNET은 2017년에 설립된 중국 장시성 기반의 기업으로, 산업 자동화 및 신에너지 분야에서 글로벌 선도 기업을 목표로 하고 있다. 주요 제품으로는 AC 드라이브, 전기차 모터 컨트롤러, 태양광 인버터, 서보 및 소프트 스타터, 변압기, 초크(choke) 등이 있으며, 이들은 공작기계, 섬유, 포장, 인쇄, 플라스틱, 제지, 제약, 유전, 화학, 엘리베이터, 크레인, 케이블, 세라믹, 빌딩 자동화, 송풍기 및 워터펌프, 차량, 철도 견인 등 다양한 산업 분야에 활용되고 있다. | E59: SinNET, established in 2017 in Jiangxi Province, China, is committed to becoming a globally leading provider of products and services in industrial automation and new energy. The company specializes in AC drives, electric vehicle motor controllers, solar inverters, servo systems and soft starters, transformers, and chokes. Its products are widely applied in machine tools, textiles, packaging, printing, plastics, paper making, pharmaceuticals, oil fields, chemicals, elevators, cranes, cables, ceramics, building automation, fans & water pumps, vehicles, rail traction, and many other industrial fields. | G59: Exhibitor | H59: InterBattery Europe 2025 | I59: C3.575 | J59: 1F | K59: {=XLOOKUP(I59, Sheet1!$A:$A, Sheet1!$B:$B, "")} -> 3271 | L59: {=XLOOKUP(I59, Sheet1!$A:$A, Sheet1!$C:$C, "")} -> 258 | M59: 산업 자동화; 신에너지; AC 드라이브; 전기차 모터 컨트롤러; 태양광 인버터; 서보 시스템; 소프트 스타터; 변압기; 초크; 다양한 산업용 전자부품 | N59: Industrial Automation; New Energy; AC Drives; EV Motor Controllers; Solar Inverters; Servo Systems; Soft Starters; Transformers; Chokes; Industrial Electronic Components
A60: Huizhou Carku Technology Co., Ltd | B60: Huizhou Carku Technology Co., Ltd | C60: China | D60: Huizhou Carku Technology Co., Ltd.는 2011년에 설립되어 중국 광동성 후이저우 시 “China-Korea (Huizhou) Industrial Park(Phase I)”에 본사를 둔 하이테크 기업으로, 리튬 배터리 응용 제품의 연구개발, 생산 및 판매를 전문으로 한다. 주요 제품군으로는 자동차 점프 스타터(Car Jump Starter), 휴대용 파워 스테이션(Portable Power Station), 트럭용 스타팅 배터리(Heavy Truck Starting Battery), 인텔리전트 가전, 전동 공구 등이 있으며, ODM/OEM 솔루션을 제공하고 글로벌 시장(100여 개국 이상)에 수출 중이다. 품질 시스템 인증(ISO 9001, IATF 16949, 기타 다수)과 인증된 제품 안전성(UL, CE, FCC, RoHS 등)을 보유하며, 사용자에게 스마트 에너지 제품으로 삶의 질 향상을 도모하고 있다 | E60: Huizhou Carku Technology Co., Ltd., established in 2011 and headquartered in Huizhou, Guangdong Province, China, specializes in the R&D, production, and sale of lithium battery-application products. Its key product lines include car jump starters, portable power stations, heavy truck starting batteries, intelligent home appliances, power tools, etc., and the company offers OEM/ODM services. Carku exports to more than 100 countries across six continents and holds multiple certifications including ISO 9001, IATF 16949, UL, CE, FCC, and RoHS, positioning itself as a global supplier of smart energy | F60: http://www.carku.com/ | G60: Exhibitor | H60: InterBattery Europe 2025 | I60: C3.679 | J60: 1F | K60: {=XLOOKUP(I60, Sheet1!$A:$A, Sheet1!$B:$B, "")} -> 3184 | L60: {=XLOOKUP(I60, Sheet1!$A:$A, Sheet1!$C:$C, "")} -> 195 | M60: 리튬 배터리 응용 제품; 자동차 점프 스타터; 휴대용 파워 스테이션; 트럭 스타팅 배터리; 전동 공구; 인텔리전트 가전; ODM/OEM 제품; 글로벌 스마트 에너지 솔루션 | N60: Lithium Battery Application Products; Car Jump Starters; Portable Power Stations; Heavy Truck Starting Batteries; Power Tools; Smart Home Appliances; OEM/ODM Solutions; Global Smart Energy Solutions
A61: Zhonghai Chao ( hebei ) New Energy Technology Co.,Ltd | B61: Zhonghai Chao ( hebei ) New Energy Technology Co.,Ltd. | C61: China | D61: Zhonghai Chao (Hebei) New Energy Technology Co., Ltd.는 중국 허베이성 스자좡(Shijiazhuang) 하이테크존 고등기술구(Innovation Building)에 위치한 업체로, 상업 및 산업용 정지형(Stationary) 에너지 저장 시스템(ESS), 전력망 사업자용 저장 시스템, 무정전 전원 공급(UPS), 저장 시스템용 전력 전자기기(파워 일렉트로닉스), 에너지 저장 시스템의 EPC 계약 및 프로젝트 개발을 주요 사업으로 수행하며, 고효율 시스템을 제공해 전력 안정성 및 재생에너지 통합에 기여하고 있다. | E61: Zhonghai Chao (Hebei) New Energy Technology Co., Ltd., based in the High-Tech Zone of Shijiazhuang, Hebei Province, China, specializes in stationary energy storage systems for commercial, industrial, and grid operator applications, uninterruptible power supply (UPS) systems, power electronics for storage, and EPC contracting and project development for energy storage systems. The company aims to deliver reliable and efficient solutions for energy storage and power stability in renewable energy integration. | F61: http://www.hicces.cc/ | G61: Exhibitor | H61: InterBattery Europe 2025 | I61: C3.580 | J61: 1F | K61: {=XLOOKUP(I61, Sheet1!$A:$A, Sheet1!$B:$B, "")} -> 3189 | L61: {=XLOOKUP(I61, Sheet1!$A:$A, Sheet1!$C:$C, "")} -> 215 | M61: 정지형 에너지 저장 시스템; 상업/산업 ESS; 전력망 저장 시스템; 무정전 전원(UPS); 전력 전자 시스템; EPC 계약 및 프로젝트 개발 | N61: Stationary Energy Storage Systems; Commercial/Industrial ESS; Grid Operator Storage Systems; Uninterruptible Power Supply (UPS); Power Electronics for Storage; EPC / Project Development for Energy Storage
A62: Guangzhou HYNER Energy Co., Ltd. | B62: Guangzhou HYNER Energy Co., Ltd. | C62: China | D62: Guangzhou HYNER Energy Co., Ltd.는 중국 광둥성 광저우 황푸구에 본사를 둔 에너지 저장 및 배터리 시스템 전문기업으로, 상업·산업용 및 유틸리티 및 전력망 운영자용 정지형(Stationary) 에너지 저장 시스템(ESS), 배터리 관리 시스템(BMS), 저장 시스템의 냉각/온도 관리 기술 등을 개발·제조하며, 제품 및 시스템 공급을 통해 에너지 전환과 전력망 안정성 강화에 기여하고 있다. | E62: Guangzhou HYNER Energy Co., Ltd., based in Huangpu District, Guangzhou, Guangdong, China, is a stationary energy storage and battery systems company that designs and manufactures stationary energy storage solutions for commercial, industrial, and utility/grid-operator applications, battery management systems (BMS), and cooling/temperature management systems for storage. The company aims to advance energy transition and enhance grid reliability through its ESS and system technologies. | F62: http://hyneress.com/ | G62: Exhibitor | H62: InterBattery Europe 2025 | I62: C3.750 | J62: 1F | K62: {=XLOOKUP(I62, Sheet1!$A:$A, Sheet1!$B:$B, "")} -> 3556 | L62: {=XLOOKUP(I62, Sheet1!$A:$A, Sheet1!$C:$C, "")} -> 91 | M62: 정지형 에너지 저장 시스템; 상업/산업 ESS; 유틸리티 및 전력망용 ESS; 배터리 관리 시스템(BMS); 냉각 및 온도 관리; 전력망 안정성 | N62: Stationary Energy Storage Systems; Commercial/Industrial ESS; Utility & Grid-Operator ESS; Battery Management Systems; Cooling & Temperature Management; Grid Reliability
A63: Nanjing Ifusion Technology Co.,Ltd | B63: Nanjing Ifusion Technology Co.,Ltd. | C63: China | D63: Nanjing IFusion Technology(난징 이퓨전 테크놀로지)는 중국 장쑤성 난징시에 본사를 둔 신재생에너지 기업으로, 마이크로 인버터, 주택용 ESS(에너지 저장 시스템), 태양광 인버터 및 주거형 태양광(발코니 PV) 시스템 등을 개발·생산하며 리튬 인산철(LFP) 기반의 에너지 저장 배터리를 포함한 제품을 제공한다. 또한 제품의 IP67 보호등급, 고전류 밀도, 내구성과 안전성 확보를 위한 설계 및 품질관리 시스템을 갖추고 있으며, 글로벌 인증(TUV, CE, EMC 등)을 확보하고 있다. | E63: Nanjing IFusion Technology Co., Ltd., based in Nanjing, Jiangsu Province, China, is a clean energy company specializing in solar energy conversion and storage solutions. Its product line includes micro-inverters (600–2000 VA), residential inverters, all-in-one hybrid systems, and energy storage batteries (LFP-based), as well as balcony PV systems. Products are designed with high current density, IP67 protection, and robust safety features, and have obtained international certifications such as TUV, CE, and EMC. | F63: http://www.ifusion-tech.com/ | G63: Exhibitor | H63: InterBattery Europe 2025 | I63: C3.762 | J63: 1F | K63: {=XLOOKUP(I63, Sheet1!$A:$A, Sheet1!$B:$B, "")} -> 3433 | L63: {=XLOOKUP(I63, Sheet1!$A:$A, Sheet1!$C:$C, "")} -> 89 | M63: 태양광 인버터; 마이크로 인버터; 주택용 ESS; 배터리 저장 솔루션; LFP 배터리; 제품 보호 등급(IP67); 제품 인증; 발코니 태양광 시스템; 에너지 변환·전력 전자 기술 | N63: Solar Inverters; Micro-inverters; Residential ESS; Battery Storage Solutions; LFP Batteries; Protection Rating (IP67); Product Certifications; Balcony PV Systems; Power Conversion Technology
A64: ANHUI SHENGXIN ALUMINIUM CORPORATION LIMITED | B64: ANHUI SHENGXIN ALUMINIUM CORPORATION LIMITED | C64: China | D64: Anhui Shengxin Aluminium Corporation Limited(약칭 Shengxin)는 중국 안후이성 Xuancheng 경제기술개발구에 본사를 둔 알루미늄 프로파일 전문 제조기업으로, 2003년에 설립되었으며 연간 10만 톤 이상의 알루미늄 프로파일 생산능력, 1,500여 명의 직원, 350,000㎡ 이상의 공장을 보유하고 있다. 주요 제품은 정밀 압출 알루미늄 프로파일, 창호 및 건축용 프로파일, 태양광 모듈 프레임 및 브래킷, 산업 구조용 프로파일 등이 있으며, 표면 처리(아노다이징·파우더 코팅·목재 무늬/wood grain 처리 등), CNC 가공, 대형 단면 프로파일 생산 등이 가능하다. “고품질 알루미늄 프로파일” 제공을 목표로 국내외 창호·건축·태양광·자동차·ESS 구조 프로파일 시장을 대상으로 활동 중이다. | E64: Anhui Shengxin Aluminium Corporation Limited (Shengxin), headquartered in Xuancheng Economic & Technical Development Zone, Anhui Province, China, was established in 2003 and has developed into a leading aluminum profile manufacturer with over 100,000 metric tons annual production capacity, a workforce exceeding 1,500, and a factory area of around 350,000 square meters. Its main products include precision aluminum extrusion profiles, architectural profiles for windows and doors, frames and brackets for solar modules, industrial structural profiles, with capabilities including anodizing, powder coating, wood-grain surface treatments, CNC machining, and production of large cross-section profiles. Shengxin serves domestic and international markets in architecture, solar energy, automotive and ESS structural applications. | F64: http://www.shengxinglobal.com/ | G64: Exhibitor | H64: InterBattery Europe 2025 | I64: C3.775 | J64: 1F | K64: {=XLOOKUP(I64, Sheet1!$A:$A, Sheet1!$B:$B, "")} -> 3297 | L64: {=XLOOKUP(I64, Sheet1!$A:$A, Sheet1!$C:$C, "")} -> 130 | M64: 알루미늄 프로파일; 정밀 압출 프로파일; 건축 창호/커튼월 프로파일; 태양광 프레임 및 브래킷; 산업 구조용 프로파일; 표면 처리; CNC 가공; 글로벌 수출 | N64: Aluminum Profiles; Precision Extruded Profiles; Architectural Window & Curtain Wall Profiles; Solar Module Frames & Brackets; Industrial Structural Profiles; Surface Treatments; CNC Machining; Global Export
A65: Zhejiang Sinopont Technology Co., Ltd. | B65: Zhejiang Sinopont Technology Co., Ltd. | C65: China | D65: Zhejiang Sinopont Technology Co., Ltd.는 2006년 설립되어 중국 저장성 항저우시 샤오산구 소취안진에 본사를 둔 태양광 모듈용 캡슐란트(encapsulant) 필름 제조 전문기업으로, EVA, POE, 화이트 필름 등 다양한 종류의 캡슐화 필름(R&D·제조·판매)을 통하여 태양광·모듈 산업에 공급하며, 제품은 유럽·미국·동남아·아프리카 등지로 수출되고 있다. | F65: http://www.sinopont.com/en/ | G65: Exhibitor | H65: InterBattery Europe 2025 | I65: C3.783 | J65: 1F | K65: {=XLOOKUP(I65, Sheet1!$A:$A, Sheet1!$B:$B, "")} -> 3221 | L65: {=XLOOKUP(I65, Sheet1!$A:$A, Sheet1!$C:$C, "")} -> 130 | M65: 태양광 캡슐란트 필름; EVA 필름; POE 필름; 화이트 필름; 모듈용 필름; 태양광 소재; 수출 기업 | N65: Solar Encapsulant Films; EVA Films; POE Films; White Films; Module-Film Materials; Solar Materials; Export Company
A66: Haicen Antech Power (Qingdao) Co., Ltd. | B66: Haicen Antech Power (Qingdao) Co., Ltd. | C66: China | D66: Haicen Antech Power (Qingdao)는 중국 청도에 본사를 둔 리튬 배터리 전문기업으로, LiFePO₄(LFP) 리튬배터리 셀과 ESS 모듈 및 팩(PACK)을 연구·제조하며, 심플라인(slimline) 배터리, 딥사이클 배터리, 트롤링모터 및 골프카트용 배터리, 높은 전압 시스템(48V, 512V 등) 제품군을 제공한다. 가정, 산업, 상업용 저장장치(ESS) 및 이동형 응용(예: 경량 전기차, 보트, 운송용 장비 등)에 사용되며, 자동화 생산라인, 품질 및 추적 시스템을 갖추고 있으며 UL, IEC, RoHS, CE 안전·성능 인증을 보유하고 있다. | E66: Haicen Antech Power (Qingdao) Co., Ltd., headquartered in Qingdao, China, is a lithium battery specialist manufacturing LiFePO₄ (LFP) cells, ESS modules and packs. Their product range includes slimline batteries, deep cycle batteries, batteries for trolling motors and golf carts, and high-voltage systems such as 48V and 512V configurations. These are used in residential, industrial, commercial, and mobile applications such as light EVs, marine, and transport equipment. The company operates with automated production lines, robust quality and traceability systems, and holds safety and performance certifications including UL, IEC, RoHS, and CE. | F66: http://www.haicenpower.net/ | G66: Exhibitor | H66: InterBattery Europe 2025 | I66: C3.782 | J66: 1F | K66: {=XLOOKUP(I66, Sheet1!$A:$A, Sheet1!$B:$B, "")} -> 3197 | L66: {=XLOOKUP(I66, Sheet1!$A:$A, Sheet1!$C:$C, "")} -> 87 | M66: 리튬 배터리; LiFePO₄ 배터리; ESS 모듈 & 팩; 딥사이클 배터리; 고전압 시스템; 이동형 & 상업용 응용; 자동화 생산라인; 인증 기본 설비 | N66: Lithium Batteries; LiFePO₄ Batteries; ESS Modules & Packs; Deep Cycle Batteries; High-Voltage Systems; Mobile & Commercial Applications; Automated Production; Certified Safety & Performance
A67: Jiangxi Ruiwei New Energy Co.,Ltd. | B67: Jiangxi Ruiwei New Energy Co.,Ltd. | C67: China | D67: Jiangxi Ruiwei New Energy Co., Ltd.는 중국 장시성 기반의 고신기술 기업으로, 2010년에 설립되었으며 연구개발·제조·판매를 통합하여 운영되고 있다. 공장은 약 20,000㎡ 이상의 면적을 차지하며, 연구개발팀을 포함한 기술 인력이 있으며, 주요 제품으로는 무보수 유지보수 불요형 VRLA 배터리, GEL 배터리, 태양광 전용 배터리, 전면 터미널 배터리 등이 있다. 새로 확인된 1688.com 프로필 페이지를 통해 제품 판매 및 기업 프로필이 공개되어 있어 사업 활동 및 제품 라인에 대한 외부 접속 가능성이 확인됨. | E67: Jiangxi Ruiwei New Energy Co., Ltd., founded in 2010 in Jiangxi Province, China, is a high-tech enterprise integrating R&D, manufacturing, and sales in the battery sector. Its main product lines include maintenance-free VRLA batteries, GEL batteries, solar-dedicated batteries, and front terminal batteries. A company profile and product offerings are also visible on a commercial platform page (1688.com), confirming active sales and product visibility. | F67: https://jxruiwei8888.1688.com/ | G67: Exhibitor | H67: InterBattery Europe 2025 | I67: C3.472 | J67: 1F | K67: {=XLOOKUP(I67, Sheet1!$A:$A, Sheet1!$B:$B, "")} -> 3281 | L67: {=XLOOKUP(I67, Sheet1!$A:$A, Sheet1!$C:$C, "")} -> 280 | M67: VRLA 유지보수-불요 배터리; GEL 배터리; 태양광 전용 배터리; 전면 터미널 배터리; 배터리 설계 및 제조; 연구개발; 제품 판매 플랫폼 | N67: VRLA Maintenance-Free Batteries; GEL Batteries; Solar-Dedicated Batteries; Front Terminal Batteries; Battery Design & Manufacturing; R&D; Product Sales Platform
A68: Shenzhen Jieyo Technology Co., Ltd | B68: Shenzhen Jieyo Technology Co., Ltd | C68: China | D68: Shenzhen Jieyo Technology Co., Ltd.(약칭 JIEYO)는 주로 리튬 이온 및 Ni-MH 배터리 셀·팩, 휴대용 파워 스테이션, 상업 및 주택용 에너지 저장 시스템(ESS), 벽걸이형/랙마운트형/스택가능 ESS 등 다양한 배터리 및 에너지 저장 솔루션을 개발·제조·판매하는 기업으로, 엄격한 품질 관리 체계하에 셀에서 팩, 팩에서 시스템까지 One-stop 서비스를 제공하며 OEM/ODM도 지원한다. | E68: Shenzhen Jieyo Technology Co., Ltd. (JIEYO) is a manufacturer specializing in lithium-ion and Ni-MH battery cells and packs, portable power stations, and energy storage system (ESS) solutions for residential, commercial, and industrial applications. The company provides one-stop services from cell to pack to system, maintains strict quality control throughout the production process, supports OEM/ODM customization, and offers wall-mounted, rack-mounted, stackable, and portable ESS offerings. | F68: http://www.jybattery.net/ | G68: Exhibitor | H68: InterBattery Europe 2025 | I68: C3.476 | J68: 1F | K68: {=XLOOKUP(I68, Sheet1!$A:$A, Sheet1!$B:$B, "")} -> 3263 | L68: {=XLOOKUP(I68, Sheet1!$A:$A, Sheet1!$C:$C, "")} -> 280 | M68: 리튬이온 배터리; Ni-MH 배터리; 휴대용 파워 스테이션; 주택/상업/산업 ESS; 벽걸이형 / 랙형 / 스택형 시스템; OEM/ODM 배터리 솔루션; 품질 관리 | N68: Lithium-Ion Batteries; Ni-MH Batteries; Portable Power Stations; Residential/Commercial/Industrial ESS; Wall-mounted / Rack / Stackable Systems; OEM/ODM Battery Solutions; Quality Control
A69: Guangdong QianWei Precision Connector Co.,Ltd. | B69: Guangdong QianWei Precision Connector Co.,Ltd. | C69: China | D69: Guangdong QianWei Precision Connector Co., Ltd.(“乾威精密连接器有限公司”)는 2012년에 설립된 중국 광동성 동관시(Changping, Dongguan)의 정밀 커넥터 단자 및 관련 인터커넥션 부품 전문 기업으로, 터미널 단자(terminals), 커넥터(connectors), 절연 소켓·하우징류(insulation housings), 와이어 침핀 및 렉(cable lugs), 자동차용 단자 및 특수 단자, 맞춤형 비표준 단자(non-standard/custom terminals) 등 다양한 제품을 연구개발 및 제조한다. 회사는 40,000m² 규모의 생산시설, 300여 대의 국제 수준 설비, ISO9001, IATF16949, ISO13485 등 품질/안전 인증을 보유하고 있으며, 무연 전기도금(lead-free plating), 친환경 인증(ROHS, REACH) 제품을 제공함으로써 신에너지차, 태양광/에너지 저장 산업, 산업자동화, 자동차 전장 등 여러 산업부문에 부품을 공급하고 있다. | E69: Guangdong QianWei Precision Connector Co., Ltd., established in 2012 and headquartered in Changping Town, Dongguan City, Guangdong Province, China, is a precision connector terminal and interconnection components manufacturer. Its product portfolio includes terminals, connectors, insulated housings and sockets, wire lugs, automotive terminals, special/custom terminals, and non-standard connector solutions. QianWei operates a 40,000 square meter production facility with over 300 advanced international equipment, holds certifications such as ISO9001, IATF16949, ISO13485, and supplies lead-free plated, ROHS/REACH compliant components to new energy vehicles, photovoltaic & energy storage, industrial automation, automotive electronics, and related fields. | F69: http://www.cnqwt.com/ | G69: Exhibitor | H69: InterBattery Europe 2025 | I69: C3.675 | J69: 1F | K69: {=XLOOKUP(I69, Sheet1!$A:$A, Sheet1!$B:$B, "")} -> 3239 | L69: {=XLOOKUP(I69, Sheet1!$A:$A, Sheet1!$C:$C, "")} -> 195 | M69: 커넥터 단자; 절연 하우징; 와이어 단자; 자동차 단자; 맞춤형 단자 / 비표준 단자; 신에너지 차량 부품; 태양광 및 ESS 부품; 산업자동화 부품; 친환경/무연 도금; 품질 인증 제품 | N69: Connector Terminals; Insulated Housings; Wire Lugs; Automotive Terminals; Custom / Non-standard Terminals; New Energy Vehicle Components; Solar & ESS Components; Industrial Automation Components; Lead-Free / Eco-friendly Plating; Certified Products
A70: HomSolar (Shenzhen) Technology Co., Ltd. | B70: HomSolar (Shenzhen) Technology Co., Ltd. | C70: China | D70: HomSolar(Shenzhen) Technology Co., Ltd.는 중국 광동성 심천시에 본사를 둔 에너지 저장 및 태양광 제품 전문 기업으로, 리튬이온 배터리(LiFePO₄) 기반의 홈·오프그리드 ESS, 가정용 전력벽(Wall Power / Power Wall), 포터블 파워스테이션, 랙형·캐비닛형 시스템 등 다양한 저장 솔루션을 개발·제조한다. 다양한 제품군과 글로벌 판매 플랫폼 이용을 통해 전 세계 고객에게 고효율, 고안전성의 제품을 제공하고 있으며, 태양광 인버터 및 시스템 통합도 사업 영역에 포함한다. | E70: HomSolar (Shenzhen) Technology Co., Ltd., headquartered in Shenzhen, Guangdong Province, China, is a manufacturer specialising in solar energy and energy storage systems, notably LiFePO₄-based home/off-grid ESS, power walls, portable power stations, rack/cabinet energy storage solutions. The company also integrates solar inverters and provides system solutions, selling its products via global platforms and serving international customers with high-efficiency, high-safety energy storage offerings. | F70: http://www.sz-homsolar.com | G70: Exhibitor | H70: InterBattery Europe 2025 | I70: C3.677 | J70: 1F | K70: {=XLOOKUP(I70, Sheet1!$A:$A, Sheet1!$B:$B, "")} -> 3218 | L70: {=XLOOKUP(I70, Sheet1!$A:$A, Sheet1!$C:$C, "")} -> 196 | M70: 에너지 저장 시스템(ESS); 가정/오프그리드 ESS; 포터블 파워스테이션; 태양광 인버터/시스템 통합; 리튬이온 배터리; 저장솔루션 캐비닛/랙형 제품; 월 패널/전력벽 | N70: Energy Storage Systems (ESS); Home / Off-Grid ESS; Portable Power Stations; Solar Inverters / System Integration; Lithium-Ion Batteries; Rack / Cabinet Storage Solutions; Power Wall / Panel Storage
A71: JIANGXI OYF VEHICLE INDUSTRY CO., LTD | B71: JIANGXI OYF VEHICLE INDUSTRY CO., LTD | C71: China | D71: Jiangxi OYF Vehicle Industry Co., Ltd.(오우야페이)는 2003년에 설립된 중국 장시성(Taihe County, Ji’an City)의 리튬 배터리 전문 기업으로, “Jiangxi Xupai New Energy(江西寻派新能源)” 브랜드로 운영 중이다. 4만2천㎡ 규모(약 63에이커)의 공장과 자산 투자 1억 8천만 위안을 바탕으로, 전동차(EV), 전기 스쿠터, 전기자전거, 삼륜/사륜 저속 전기차 및 에너지 저장 시스템(ESS), 파워 툴, 야외 백업 전원과 휴대용 전원 장치 생산에 주력하며, ISO 9001 인증을 포함한 품질관리 절차와 엄격한 성능 테스트 체계를 갖추고 있다. | E71: Jiangxi OYF Vehicle Industry Co., Ltd., founded in 2003 and operating under the brand Jiangxi Xupai New Energy, is a lithium battery and electric vehicle company based in Taihe County, Ji’an City, Jiangxi Province, China. With a production area of approximately 42,000 square meters and capital investment of roughly CNY 180 million, OYF designs, manufactures, and supplies electric motorcycles, electric bicycles, electric scooters, low-speed four-wheel electric vehicles, energy storage systems (ESS), outdoor backup power, and portable power devices. It maintains ISO 9001 quality certification and conducts rigorous testing for capacity, internal resistance, cycle life, safety, and overall product performance. | F71: http://www.oyfebike.com/ | G71: Exhibitor | H71: InterBattery Europe 2025 | I71: C3.574 | J71: 1F | K71: {=XLOOKUP(I71, Sheet1!$A:$A, Sheet1!$B:$B, "")} -> 3242 | L71: {=XLOOKUP(I71, Sheet1!$A:$A, Sheet1!$C:$C, "")} -> 217 | M71: 리튬 배터리; 전기 스쿠터; 전기자전거; 전동 오토바이; 저속 전기차; ESS (에너지 저장 시스템); 야외 백업 전원/휴대용 전원장치; 제품 안전 및 성능 테스트 | N71: Lithium Batteries; Electric Scooters; Electric Bicycles; Electric Motorcycles; Low‐Speed EVs; Energy Storage Systems (ESS); Outdoor Backup & Portable Power; Product Safety & Performance Testing
A72: Spaceflight Power Supply Co., Ltd | B72: Spaceflight Power Supply Co., Ltd | C72: China | D72: SPACEFLIGHT POWER SUPPLY (LONGNAN) CO., LTD.는 30년 이상의 역사를 가진 중국의 전문 배터리 제조 기업으로, 고품질 자동차용 배터리와 더불어 첨단 에너지 저장용 배터리 및 전기차 배터리를 생산하고 있다. 회사는 안정성, 내구성, 효율성을 갖춘 다양한 응용 분야 배터리 솔루션을 제공하며, 리드애시드 배터리부터 최신 전동화 응용 제품에 이르기까지 글로벌 시장에 공급하고 있다. | E72: SPACEFLIGHT POWER SUPPLY (LONGNAN) CO., LTD. is a professional battery manufacturing company with a 30-year history, specializing in producing high-quality batteries for various applications. The company specializes in manufacturing automotive batteries, as well as advanced storage and electric vehicle batteries. | F72: http://www.hang-tian.com/ | G72: Exhibitor | H72: InterBattery Europe 2025 | I72: C3.576 | J72: 1F | K72: {=XLOOKUP(I72, Sheet1!$A:$A, Sheet1!$B:$B, "")} -> 3218 | L72: {=XLOOKUP(I72, Sheet1!$A:$A, Sheet1!$C:$C, "")} -> 215 | M72: 자동차 배터리; 에너지 저장 배터리; 전기차 배터리; 리드애시드 배터리; 첨단 배터리 솔루션; 글로벌 공급망 | N72: Automotive Batteries; Energy Storage Batteries; Electric Vehicle Batteries; Lead-Acid Batteries; Advanced Battery Solutions; Global Supply Chain
A73: Ostar Power Technology Co., Ltd. | B73: Ostar Power Technology Co., Ltd. | C73: China | D73: Ostar Power는 2002년에 설립된 중국 장시성 소재 전문 배터리 제조 및 수출기업으로, VRLA/SLA 배터리(AGM, GEL 타입)와 LiFePO₄ 배터리를 중심으로 연구·개발·제조·유통을 통합 운영하며, 19개 시리즈에 걸쳐 다양한 용량(0.5Ah부터 3000Ah까지)의 제품을 100여 개 이상의 국가에 공급한다. 제품군은 일반용, 딥사이클, 태양광, 전기차, 고속 방전, 장수명, 프론트 터미널, 고온용, 리드 카본, OPzV/OPzS, 견인용, 오토바이/자동차 등으로 구성되어 있으며, 엄격한 품질 시스템과 ISO9001, UL, CE, UN38.3 등의 인증을 보유하고 있다. | E73: Ostar Power (Jiangxi Ostar Power Tech Co., Ltd.), founded in 2002 and based in Jiangxi, China, is a manufacturer and exporter specializing in VRLA/SLA batteries (AGM, GEL types) and LiFePO₄ batteries. The company integrates R&D, manufacturing, and distribution, offering over 400 models across 19 product series, spanning from 0.5Ah to 3000Ah capacities, for applications including general purpose, deep cycle, solar, electric vehicle, traction, motorcycle/automobile, high-temperature and front-terminal configurations. Its products are distributed in more than 100 countries, and it maintains certifications such as ISO9001, UL, CE, and UN38.3. | F73: http://www.ostar-power.com/ | G73: Exhibitor | H73: InterBattery Europe 2025 | I73: C3.772 | J73: 1F | K73: {=XLOOKUP(I73, Sheet1!$A:$A, Sheet1!$B:$B, "")} -> 3299 | L73: {=XLOOKUP(I73, Sheet1!$A:$A, Sheet1!$C:$C, "")} -> 92 | M73: VRLA/SLA 배터리; LiFePO₄ 배터리; 태양광용 배터리; 전기차 배터리; 딥사이클 배터리; 견인용 배터리; 고온 배터리; 프론트 터미널 배터리; 인증 제품; 글로벌 수출 | N73: VRLA/SLA Batteries; LiFePO₄ Batteries; Solar Batteries; Electric Vehicle Batteries; Deep Cycle Batteries; Traction Batteries; High-Temperature Batteries; Front Terminal Batteries; Certified Products; Global Export
A74: Jiangxi Yudian New Energy Technology Co., Ltd | B74: Jiangxi Yudian New Energy Technology Co., Ltd. | C74: China | D74: Jiangxi Yudian New Energy Technology Co., Ltd.는 2024년에 설립된 중국 장시성 신유시(Xinyu City)의 핵심 프로젝트로, 스마트 산업공원(Xiacun Industrial Park, Yushui District)에 위치한 약 24,000㎡ 규모의 공장에서 고품질 32700 리튬 인산철 배터리를 하루 200,000셀 생산 가능한 라인과 일일 1,000세트 배터리 팩을 조립할 수 있는 8개 팩 조립 라인을 포함한 설비를 갖추고 있다. 주요 제품은 가정용 정지형 에너지 저장 장치(residential ESS), 스마트폰/노트북/태블릿 등 저용량 모바일 응용 제품용 에너지 저장, 배터리 관리 시스템(BMS), 배터리 모듈 조립 및 시스템 설치 장비 등이다. | E74: Jiangxi Yudian New Energy Technology Co., Ltd., established in 2024 in Xinyu City, Jiangxi Province, China, is a key new energy enterprise located in Xiacun Industrial Park, Yushui District. The company occupies approximately 24,000 square meters factory, equipped with production lines capable of manufacturing 200,000 high-quality 32700 LiFePO₄ battery cells per day and eight module/pack assembly lines able to produce 1,000 battery packs daily. Its product portfolio includes stationary residential energy storage systems, low-capacity mobile storage applications (smartphones, laptops, tablets), battery management systems, and equipment for battery module production and system assembly | G74: Exhibitor | H74: InterBattery Europe 2025 | I74: C3.774 | J74: 1F | K74: {=XLOOKUP(I74, Sheet1!$A:$A, Sheet1!$B:$B, "")} -> 3278 | L74: {=XLOOKUP(I74, Sheet1!$A:$A, Sheet1!$C:$C, "")} -> 90 | M74: 정지형 에너지 저장 시스템(Residential ESS); 모바일 응용 저장장치; 리튬 인산철 배터리 셀(cell) 생산; 배터리 팩 조립; 배터리 관리 시스템(BMS); 모듈/시스템 설치 장비 | N74: Stationary Residential ESS; Low-Capacity Mobile Storage; LiFePO₄ Cell Production; Battery Pack Assembly; Battery Management Systems (BMS); Module/System Assembly Equipment
A75: Jiangsu Guoning Power Cable Co., Ltd | B75: Jiangsu Guoning Power Cable Co., Ltd | C75: China | D75: Jiangsu Guoning Power Cable Co., Ltd.는 2003년에 설립된 중국 장쑤성 난징시의 케이블 전문 제조기업으로, 태양광 케이블(solar cables), 배터리 케이블(battery cables), 제어 케이블(control cables), 전력 케이블(power cables), 전선 및 빌딩 와이어(building wires), 유연 케이블(flexible cable), 차폐 및 보호 케이블 등 다양한 유형의 전선 및 케이블 제품을 연구개발·제조·수출하며, ISO/TUV/CE 등 국내외 인증을 보유하고 고객 맞춤 케이블 설계 서비스도 제공한다. 또한, ‘국가 고신기술 기업(National High-tech Enterprise)’ 및 ‘장쑤성 고신기술 기업’으로 인정받고 있으며, 연간 생산규모 및 수출 실적을 통해 글로벌 태양광·에너지 저장 시스템(ESS) 시장에 부품을 공급 중이다. | E75: Jiangsu Guoning Power Cable Co., Ltd., founded in 2003 and located in Nanjing, Jiangsu Province, China, is a specialized manufacturer of wires and cables, including solar cables, battery cables, control cables, power cables, building and flexible wires, with customization services per client requirement. The company holds multiple domestic and international certifications such as ISO, TUV, CE, and is recognized as a National High-tech Enterprise and Jiangsu High-tech Enterprise. It supplies cable products globally, especially to solar power and energy storage (ESS) sectors. | F75: http://www.guoningcable.com/ | G75: Exhibitor | H75: InterBattery Europe 2025 | I75: C3.758 | J75: 1F | K75: {=XLOOKUP(I75, Sheet1!$A:$A, Sheet1!$B:$B, "")} -> 3482 | L75: {=XLOOKUP(I75, Sheet1!$A:$A, Sheet1!$C:$C, "")} -> 91 | M75: 태양광 케이블; 배터리 케이블; 전력 케이블; 제어 케이블; 유연 및 차폐 케이블; 케이블 설계 및 맞춤형 제조; 글로벌 수출; 인증 제품 | N75: Solar Cables; Battery Cables; Power Cables; Control Cables; Flexible & Shielded Cables; Custom Cable Design & Manufacturing; Global Export; Certified Products
A76: Q-SUN (NANJING) CO., LTD. | B76: Q-SUN (NANJING) CO., LTD. | C76: China | D76: Q-SUN (Nanjing) Co., Ltd.는 2014년 설립된 중국 기업으로, 청정 에너지 통합 솔루션을 제공하며 주로 태양광(PV) 모듈의 연구·개발·생산 및 판매를 수행한다. 난징에 국제 마케팅 센터가 있으며, Tianchang, Yancheng 등에 생산기지를 운영하며 연간 수 GW 규모의 고효율 모듈을 공급하고 있다. 제품군은 Residential, Commercial, Utility 용 PV 모듈 및 ESS솔루션을 포함하며, ISO 및 IEC 기반 인증을 확보하고 있으며, 해외 50여개국 이상으로 수출하고 있다. | E76: Q-SUN (Nanjing) Co., Ltd., founded in 2014, is a clean energy company specializing in the R&D, manufacturing, and sales of photovoltaic modules. The company is headquartered in Nanjing with production bases in Tianchang and Yancheng, delivering several gigawatts of high-efficiency solar modules annually. Its product line includes PV modules and energy storage solutions for residential, commercial, and utility applications. Q-SUN holds certifications in ISO and IEC standards and exports to over 50 countries worldwide. | F76: http://www.q-sunsolar.com/ | G76: Exhibitor | H76: InterBattery Europe 2025 | I76: C3.776 | J76: 1F | K76: {=XLOOKUP(I76, Sheet1!$A:$A, Sheet1!$B:$B, "")} -> 3260 | L76: {=XLOOKUP(I76, Sheet1!$A:$A, Sheet1!$C:$C, "")} -> 90 | M76: 태양광 모듈; 에너지 저장 솔루션(ESS); Residential/Commercial/Utility 태양광; PV 모듈 생산 및 수출; 인증제품 | N76: Photovoltaic Modules; Energy Storage Solutions (ESS); Residential / Commercial / Utility Solar; PV Module Production & Export; Certified Products
A77: SHENZHEN GRT COMMUNICATION SCIENCE & TECHNOLOGY CO.,LTD | B77: SHENZHEN GRT COMMUNICATION SCIENCE & TECHNOLOGY CO.,LTD | C77: China | D77: Shenzhen GRT Communication Science & Technology Co., Ltd.는 1993년 설립된 중국 광둥성 심천시에 본사를 두고 있으며, 배터리 하우징, 배선, 절연 부품 및 버스바(busbar) 계열의 도체 구조 부품을 연구·생산·공급하는 기업으로, 리지드(rigid) 및 라미네이티드(laminated) 버스바, 유연 플렉시블 버스바, 절연 처리된 코퍼/알루미늄 버스바 및 연결 부품 등이 주요 제품이다. 또한 배터리 모듈 조립 및 시스템 설치/조립용 장비와 부품도 공급하며, OEM/ODM 주문 제작도 가능하다. | E77: Shenzhen GRT Communication Science & Technology Co., Ltd., founded in December 1993 and based in Shenzhen, Guangdong, China, specializes in the R&D, manufacture, and supply of conductive structure components for batteries such as copper and aluminum rigid and laminated busbars, flexible connectors, insulated busbars as well as contacts, wiring and insulation components. The company also provides components and equipment for battery module manufacturing/assembly and system installation, with capabilities for OEM/ODM customization. | F77: http://www.grt.cn/ | G77: Exhibitor | H77: InterBattery Europe 2025 | I77: C3.756 | J77: 1F | K77: {=XLOOKUP(I77, Sheet1!$A:$A, Sheet1!$B:$B, "")} -> 3503 | L77: {=XLOOKUP(I77, Sheet1!$A:$A, Sheet1!$C:$C, "")} -> 92 | M77: 배터리 하우징; 버스바(busbar) 및 전도 도체 구조 부품; 절연 및 배선 부품; 버스바 라미네이티드/리지드/플렉시블; 배터리 모듈 조립 및 시스템 설치 부품; OEM/ODM 맞춤 부품 | N77: Battery Housing; Busbars & Conductive Structural Components; Insulation & Wiring Components; Laminated / Rigid / Flexible Busbars; Module & System Assembly Components; OEM/ODM Customized Parts
A78: Ningbo Duopower New Energy Electrical Technology CO., LTD | B78: Ningbo Duopower New Energy Electrical Technology CO., LTD | C78: China | D78: Ningbo Duopower New Energy Electrical Technology Co., Ltd.(두오파워)는 2023년에 설립된 중국 저장성 닝보시 소재 기업으로, 휴대형 및 가정/고정형 에너지 저장 장치(portable & fixed home energy storage)의 연구개발, 생산, 판매를 통합 운영하고 있다. 기술팀은 배터리 저장, BMS(배터리 관리 시스템), 인버터 응용 및 하드웨어·소프트웨어 호환성 모두에 역량을 갖추고 있으며, OEM/ODM 서비스를 제공하며 야외 캠핑, 비상 전원, 가정용 백업 전력 등 다양한 시나리오에 적합한 녹색 에너지 솔루션을 지원한다. | E78: Ningbo Duopower New Energy Electrical Technology Co., Ltd., founded in 2023 in Ningbo, Zhejiang Province, China, specializes in developing, manufacturing, and selling portable and fixed household energy storage products. The company integrates cutting-edge hardware and software technologies, including BMS and inverter applications, and offers OEM/ODM services. Duopower aims to deliver green energy solutions tailored for multiple scenarios such as outdoor, emergency backup, and home storage, leveraging strong technical expertise and compatibility. | F78: http://www.duopowersolutions.com/ | G78: Exhibitor | H78: InterBattery Europe 2025 | I78: C3.780 | J78: 1F | K78: {=XLOOKUP(I78, Sheet1!$A:$A, Sheet1!$B:$B, "")} -> 3218 | L78: {=XLOOKUP(I78, Sheet1!$A:$A, Sheet1!$C:$C, "")} -> 92 | M78: 에너지 저장 시스템(ESS); 휴대용 저장 장치; 가정용/고정형 ESS; OEM/ODM 배터리 솔루션; 배터리 관리 시스템(BMS); 인버터 응용; 녹색 에너지 제품 | N78: Energy Storage Systems (ESS); Portable Energy Storage; Home / Fixed ESS; OEM/ODM Battery Solutions; Battery Management Systems (BMS); Inverter Applications; Green Energy Products
A79: Jiangxi Wannianxin Micro-Electronics Co.,Ltd | B79: Jiangxi Wannianxin Micro-Electronics Co.,Ltd | C79: China | D79: Jiangxi Wannianxin Micro-Electronics Co., Ltd.(창립 2017년)는 중국 장시성 상라오(Shangrao) 만년(萬年)현에 위치하며, 약 112무(≈ 74,667㎡) 부지에 117,000㎡의 건축면적을 가진 설비를 보유하고 있다. 주요 사업은 4-12인치 반도체 집적회로(IC) 및 하이브리드 집적회로, 대용량 플래시 메모리 칩의 패키징 및 테스트, 센서류 제품의 연구개발 및 생산이며, 휴대형 파워 스테이션, 배터리 관리 시스템(BMS) 보드, 인버터 등도 글로벌 시장 수요 대응을 위해 제공하고 있다. | E79: Jiangxi Wannianxin Micro-Electronics Co., Ltd., established in February 2017, is located in Wannian County, Shangrao, Jiangxi Province, China. The company occupies a project site of 112 mu, with a built-area of about 117,000 square meters. Its core businesses include packaging and testing for 4-12 inch semiconductor integrated circuits and hybrid ICs, large capacity flash memory chips, as well as sensor products R&D and manufacturing. Additionally, it supplies portable power stations, BMS control boards, and inverters to meet global market demands. | F79: http://www.wnxjx.com/ | G79: Exhibitor | H79: InterBattery Europe 2025 | I79: C3.754 | J79: 1F | K79: {=XLOOKUP(I79, Sheet1!$A:$A, Sheet1!$B:$B, "")} -> 3524 | L79: {=XLOOKUP(I79, Sheet1!$A:$A, Sheet1!$C:$C, "")} -> 92 | M79: 반도체 패키징 및 테스트; 집적회로(IC) 제조; 하이브리드 IC; 플래시 메모리; 센서제품; 휴대형 파워스테이션; 배터리 관리 시스템(BMS); 인버터; 전자부품 제조 | N79: Semiconductor Packaging & Testing; Integrated Circuits (IC) Manufacturing; Hybrid ICs; Flash Memory; Sensor Products; Portable Power Stations; Battery Management Systems (BMS); Inverters; Electronic Components Manufacturing
A80: Hubei XYC New Energy CO.,LTD. | B80: Hubei XYC New Energy CO.,LTD. | C80: China | D80: Hubei XYC New Energy Co., Ltd.는 중국 후베이성 샤오간시 한촨시에 위치한 기업으로, 리튬 기반 배터리와 정지형 에너지 저장 시스템(ESS)을 주택용, 상업용, 산업용으로 제공하고 있다. 주요 제품에는 리튬 배터리, VRLA 배터리, 배터리 관리 시스템(BMS), 저장 시스템용 전력전자 솔루션이 포함되며, 안정적이고 효율적인 에너지 저장 솔루션을 제공한다. | E80: Hubei XYC New Energy Co., Ltd., located in Hanchuan City, Xiaogan, Hubei Province, China, specializes in lithium-based batteries and stationary energy storage systems (ESS) for residential, commercial, and industrial applications. Its main products include lithium batteries, VRLA batteries, battery management systems (BMS), and power electronics for storage, providing reliable and efficient energy storage solutions. | G80: Exhibitor | H80: InterBattery Europe 2025 | I80: C3.760 | J80: 1F | K80: {=XLOOKUP(I80, Sheet1!$A:$A, Sheet1!$B:$B, "")} -> 3464 | L80: {=XLOOKUP(I80, Sheet1!$A:$A, Sheet1!$C:$C, "")} -> 91 | M80: 리튬 기반 배터리; VRLA 배터리; 주택용 ESS; 상업/산업용 ESS; 배터리 관리 시스템(BMS); 저장시스템 전력전자 | N80: Lithium-based Batteries; VRLA Batteries; Residential ESS; Commercial/Industrial ESS; Battery Management Systems (BMS); Storage System Power Electronics
A81: HUANGHUA GUNTER HARDWARE CO., LTD | B81: HUANGHUA GUNTER HARDWARE CO., LTD | C81: China | D81: Huanghua Gunter Hardware Co., Ltd.는 2002년에 설립된 중국 허베이성(Hebei)의 산업용 하드웨어 제조기업으로, 축사용 바닥 슬랫(plastic pig slat, cast iron pig slat), 축사 급이/급수 장비, 애완동물 케이지(dog cage, dog kennel) 및 안전 울타리(safety gate) 등의 제품을 설계·생산한다. 제품은 유럽, 미국 등 해외 시장으로 수출되고 있으며 고품질과 고객 서비스를 중심 가치로 삼고 있다. | E81: Huanghua Gunter Hardware Co., Ltd., established in 2002 in Hebei Province, China, is a hardware manufacturer specializing in animal farming equipment such as pig flooring slats (plastic and cast iron), pig feeders and drinkers, pet cages and safety gates. The company exports its products to Europe, the United States, and other international markets, emphasizing high quality and customer service. | F81: https://www.hbhonde-energy.com/ | G81: Exhibitor | H81: InterBattery Europe 2025 | I81: C3.778 | J81: 1F | K81: {=XLOOKUP(I81, Sheet1!$A:$A, Sheet1!$B:$B, "")} -> 3239 | L81: {=XLOOKUP(I81, Sheet1!$A:$A, Sheet1!$C:$C, "")} -> 92 | M81: 축사 바닥 슬랫; 축사 급이·급수 장비; 애완동물 케이지; 안전 울타리; 하드웨어 제조; OEM/ODM 수출 제품 | N81: Animal farming flooring slats; Pig feeding & drinking equipment; Pet cages; Safety gates; Hardware manufacturing; OEM/ODM export products
A82: CHONGQING LIHONG FINE CHEMICALS CO., LTD. | B82: CHONGQING LIHONG FINE CHEMICALS CO., LTD. | C82: China | D82: CHONGQING LIHONG FINE CHEMICALS CO., LTD.는 2001년 10월 설립된 중국 충칭시에 본사를 둔 정밀 화학기업으로, 주력 제품은 산화 나트륨 카르복시메틸 셀룰로오스(Sodium Carboxymethyl Cellulose, CMC) 및 폴리아니온 셀룰로오스(polyanionic cellulose) 폴리머이며, 연간 CMC 생산능력은 약 30,000톤, ISO 9001 품질경영 시스템 인증 및 HALAL 인증을 보유하고 있고 식품, 세제, 치약, 세라믹, 제지, 석유시추 등 다양한 산업에 공급한다. | E82: CHONGQING LIHONG FINE CHEMICALS CO., LTD., founded in October 2001 and headquartered in Chongqing, China, specializes in the development, production, and sale of polymers such as Sodium Carboxymethyl Cellulose (CMC) and polyanionic cellulose. Its annual CMC production capacity is approximately 30,000 metric tons. The company has obtained ISO 9001 and HALAL certifications and supplies its products across multiple industries, including food, detergents, toothpaste, ceramics, paper manufacturing, and oil drilling. | F82: http://www.lihong.net/ | G82: Exhibitor | H82: InterBattery Europe 2025 | I82: C3.755 | J82: 1F | K82: {=XLOOKUP(I82, Sheet1!$A:$A, Sheet1!$B:$B, "")} -> 3540 | L82: {=XLOOKUP(I82, Sheet1!$A:$A, Sheet1!$C:$C, "")} -> 130 | M82: CMC(카르복시메틸 셀룰로오스); 폴리아니온 셀룰로오스; 정밀 화학 소재; 산업용 폴리머; 식품/세정/세제 첨가제; 종이 제조; 세라믹 및 치약 소재; 석유 시추 첨가제 | N82: Sodium Carboxymethyl Cellulose (CMC); Polyanionic Cellulose; Fine Chemical Materials; Industrial Polymers; Food / Detergent / Toothpaste Additives; Paper Manufacturing; Ceramics & Personal Care; Oil Drilling Additives
A83: Shenzhen Swalle Technology Co.,Ltd. | B83: Shenzhen Swalle Technology Co.,Ltd. | C83: China | D83: henzhen Swalle Technology Co., Ltd.는 중국 광둥성 심천시에 본사를 둔 배터리 및 에너지 저장 솔루션 전문 기업으로, 가정용 백업 파워 스테이션(Home Battery Backup), LiFePO₄ 배터리, 배터리 관리 시스템(BMS) 등을 개발·생산·판매하고 있으며 다양한 용량의 LiFePO₄ 배터리 팩(예: 12V 100Ah / 200Ah / 24V 등)을 태양광 저장 및 오프그리드용, RV/보트/비상전원 등 응용분야에 제공한다. | E83: Shenzhen Swalle Technology Co., Ltd., headquartered in Shenzhen, Guangdong, China, specializes in home battery backup, LiFePO₄ battery packs, and battery management systems (BMS). The company produces various capacity battery packs (such as 12V 100Ah, 200Ah, 24V units) used for solar energy storage, off-grid applications, RVs, boats and backup power supply, integrating design, manufacturing, and global sales. | F83: http://www.lanpwr.com/ | G83: Exhibitor | H83: InterBattery Europe 2025 | I83: C3.757 | J83: 1F | K83: {=XLOOKUP(I83, Sheet1!$A:$A, Sheet1!$B:$B, "")} -> 3519 | L83: {=XLOOKUP(I83, Sheet1!$A:$A, Sheet1!$C:$C, "")} -> 130 | M83: LiFePO₄ 배터리; 가정용 백업 전원; 에너지 저장 시스템; 배터리 팩; BMS; 태양광/오프그리드 응용; 휴대용/비상 전원 | N83: LiFePO₄ Batteries; Home Battery Backup; Energy Storage Systems; Battery Packs; Battery Management Systems (BMS); Solar / Off-Grid Applications; Portable / Backup Power
A84: China ZBB group Shanghai transformer Co., Ltd. | B84: China ZBB group Shanghai transformer Co., Ltd. | C84: China | D84: China ZBB Group Shanghai Transformer Co., Ltd.는 2006년 설립되었으며 중국 상하이 금산(진산) 산업단지에 본사를 둔 변압기 및 전력 배전장비 전문 기업으로, 등록 자본금 1억5천만 위안, 36,227㎡ 규모 부지 중 32,698㎡ 생산공장을 운영하고 있으며, 445명의 직원(기술/엔지니어 인력 포함)을 보유하고 있다. 제품군에는 110kV 이하의 전력 변압기, 특수 변압기, 정류기 변압기, 건식 변압기, 비정질 합금 변압기, 고/저압 배전반, 박스형 변전소, 풍력 및 태양광 발전소용 변전 설비 등이 있으며, 연간 주요 제품 변압기의 산출량이 약 2,808만 kVA에 달한다. 또한 ISO9001, ISO14001, ISO45001 등 품질 및 환경/안전 관리 시스템 인증을 획득하고 있으며 제품은 CE, IEC, GOST 등 국제 규격을 준수하고 해외 동남아시아, 중앙아시아, 중동, 아프리카, 유럽 등지로 수출되고 있다. | E84: China ZBB Group Shanghai Transformer Co., Ltd., established in September 2006 and located in Jinshan Industrial Zone, Shanghai, China, is a transformer and power distribution equipment specialist with a registered capital of CNY 150 million. It occupies about 36,227 square meters with a production facility area of 32,698 square meters and employs 445 staff including technical and engineering personnel. Its product range includes power transformers up to 110 kV, special transformers, rectifier transformers, dry-type transformers, amorphous alloy transformers, high/low-voltage switchgear, box-type substations, as well as wind & solar photovoltaics substation transformers. The company achieves an annual output of approximately 28.08 million kVA for its leading transformer products. It holds certifications including ISO 9001, ISO 14001, ISO 45001, and its products meet standards such as CE, IEC, GOST. ZBB exports to Southeast Asia, Central Asia, Middle East, Africa, Europe, and more. | F84: https://www.zbb.cc/ | G84: Exhibitor | H84: InterBattery Europe 2025 | I84: C3.668 | J84: 1F | K84: {=XLOOKUP(I84, Sheet1!$A:$A, Sheet1!$B:$B, "")} -> 3354 | L84: {=XLOOKUP(I84, Sheet1!$A:$A, Sheet1!$C:$C, "")} -> 155 | M84: 전력 변압기; 특수 변압기; 건식 변압기; 비정질 합금 변압기; 고/저압 배전반; 박스형 변전소; 풍력/태양광 변전 설비; 전력 배전 장비; 품질/환경/안전 인증 제품; 글로벌 수출 | N84: Power Transformers; Special Transformers; Dry-Type Transformers; Amorphous Alloy Transformers; High/Low Voltage Switchgear; Box-Type Substations; Wind & Solar Photovoltaic Substation Equipment; Power Distribution Equipment; Certified Quality/Environment/Safety Products; Global Export
...

Sheet Sheet1
A1: booth_code | B1: x | C1: y | D1: query
A2: C3.782 | B2: 3197 | C2: 87 | D2: UPDATE TBL_BOOTHS SET X_COORD = | E2: =B2 -> 3197 | F2: , Y_COORD = | G2: =C2 -> 87 | H2: WHERE NAME =' | I2: =A2 -> C3.782 | J2: '; | K2: UPDATE TBL_BOOTHS SET X_COORD = 3197 , Y_COORD = 87 WHERE NAME ='C3.782';
A3: C3.780 | B3: 3218 | C3: 92 | D3: UPDATE TBL_BOOTHS SET X_COORD = | E3: =B3 -> 3218 | F3: , Y_COORD = | G3: =C3 -> 92 | H3: WHERE NAME =' | I3: =A3 -> C3.780 | J3: '; | K3: UPDATE TBL_BOOTHS SET X_COORD = 3218 , Y_COORD = 92 WHERE NAME ='C3.780';
A4: C3.778 | B4: 3239 | C4: 92 | D4: UPDATE TBL_BOOTHS SET X_COORD = | E4: =B4 -> 3239 | F4: , Y_COORD = | G4: =C4 -> 92 | H4: WHERE NAME =' | I4: =A4 -> C3.778 | J4: '; | K4: UPDATE TBL_BOOTHS SET X_COORD = 3239 , Y_COORD = 92 WHERE NAME ='C3.778';
A5: C3.776 | B5: 3260 | C5: 90 | D5: UPDATE TBL_BOOTHS SET X_COORD = | E5: =B5 -> 3260 | F5: , Y_COORD = | G5: =C5 -> 90 | H5: WHERE NAME =' | I5: =A5 -> C3.776 | J5: '; | K5: UPDATE TBL_BOOTHS SET X_COORD = 3260 , Y_COORD = 90 WHERE NAME ='C3.776';
A6: C3.774 | B6: 3278 | C6: 90 | D6: UPDATE TBL_BOOTHS SET X_COORD = | E6: =B6 -> 3278 | F6: , Y_COORD = | G6: =C6 -> 90 | H6: WHERE NAME =' | I6: =A6 -> C3.774 | J6: '; | K6: UPDATE TBL_BOOTHS SET X_COORD = 3278 , Y_COORD = 90 WHERE NAME ='C3.774';
A7: C3.772 | B7: 3299 | C7: 92 | D7: UPDATE TBL_BOOTHS SET X_COORD = | E7: =B7 -> 3299 | F7: , Y_COORD = | G7: =C7 -> 92 | H7: WHERE NAME =' | I7: =A7 -> C3.772 | J7: '; | K7: UPDATE TBL_BOOTHS SET X_COORD = 3299 , Y_COORD = 92 WHERE NAME ='C3.772';
A8: C3.770 | B8: 3333 | C8: 90 | D8: UPDATE TBL_BOOTHS SET X_COORD = | E8: =B8 -> 3333 | F8: , Y_COORD = | G8: =C8 -> 90 | H8: WHERE NAME =' | I8: =A8 -> C3.770 | J8: '; | K8: UPDATE TBL_BOOTHS SET X_COORD = 3333 , Y_COORD = 90 WHERE NAME ='C3.770';
A9: C3.762 | B9: 3433 | C9: 89 | D9: UPDATE TBL_BOOTHS SET X_COORD = | E9: =B9 -> 3433 | F9: , Y_COORD = | G9: =C9 -> 89 | H9: WHERE NAME =' | I9: =A9 -> C3.762 | J9: '; | K9: UPDATE TBL_BOOTHS SET X_COORD = 3433 , Y_COORD = 89 WHERE NAME ='C3.762';
A10: C3.760 | B10: 3464 | C10: 91 | D10: UPDATE TBL_BOOTHS SET X_COORD = | E10: =B10 -> 3464 | F10: , Y_COORD = | G10: =C10 -> 91 | H10: WHERE NAME =' | I10: =A10 -> C3.760 | J10: '; | K10: UPDATE TBL_BOOTHS SET X_COORD = 3464 , Y_COORD = 91 WHERE NAME ='C3.760';
